<mujoco model="go2_arm">
  <compiler angle="radian" meshdir="assets" autolimits="true" />

  <default>
    <default class="go2">
      <default class="visual">
        <geom type="mesh" contype="0" conaffinity="0" density="0" group="2"/>
      </default>
      <default class="collision">
        <geom priority="1" condim="6" group="3"/>
      </default>
      <site rgba="1 0 0 1" group="5"/>
    </default>
    
    <default class="d1">
      <site group="5" size="0.005" rgba="0 1 0 1"/>
      <joint axis="0 0 1"/>
      <default class="d1_visual">
        <geom type="mesh" contype="0" conaffinity="0" density="0" group="2" material="black"/>
      </default>
      <default class="d1_collision">
        <geom group="3" type="mesh"/>
      </default>
      <default class="finger">
        <joint type="slide"/>
      </default>
    </default>
  </default>

  <asset>
    <material name="metal" rgba=".9 .95 .95 1" />
    <material name="black" rgba="0 0 0 1" />
    <material name="white" rgba="1 1 1 1" />
    <material name="gray" rgba="0.671705 0.692426 0.774270 1" />

    <mesh file="base_0.obj" />
    <mesh file="base_1.obj" />
    <mesh file="base_2.obj" />
    <mesh file="base_3.obj" />
    <mesh file="base_4.obj" />
    <mesh file="hip_0.obj" />
    <mesh file="hip_1.obj" />
    <mesh file="thigh_0.obj" />
    <mesh file="thigh_1.obj" />
    <mesh file="thigh_mirror_0.obj" />
    <mesh file="thigh_mirror_1.obj" />
    <mesh file="calf_0.obj" />
    <mesh file="calf_1.obj" />
    <mesh file="calf_mirror_0.obj" />
    <mesh file="calf_mirror_1.obj" />
    <mesh file="foot.obj" />
    
    <mesh file="base_link.obj"/>
    <mesh file="Link1.obj"/>
    <mesh file="Link2.obj"/>
    <mesh file="Link3.obj"/>
    <mesh file="Link4.obj"/>
    <mesh file="Link5.obj"/>
    <mesh file="Link6.obj"/>
    <mesh file="Link7_1.obj"/>
    <mesh file="Link7_2.obj"/>
  </asset>

  <worldbody>
    <body name="base_link" pos="0 0 0.445" childclass="go2">
      <inertial pos="0.021112 0 -0.005366" quat="-0.000543471 0.713435 -0.00173769 0.700719" mass="6.921" diaginertia="0.107027 0.0980771 0.0244531" />
      <freejoint name="floating_base_joint"/>
      <geom mesh="base_0" material="black" class="visual" />
      <geom mesh="base_1" material="black" class="visual" />
      <geom mesh="base_2" material="black" class="visual" />
      <geom mesh="base_3" material="white" class="visual" />
      <geom mesh="base_4" material="gray" class="visual" />
      <geom name="base1_collision" size="0.1881 0.04675 0.057" type="box" class="collision" />
      <geom name="base2_collision" size="0.05 0.045" pos="0.285 0 0.01" type="cylinder" class="collision" />
      <geom name="base3_collision" size="0.047" pos="0.293 0 -0.06" type="sphere" class="collision" />
      <site name="imu" pos="-0.02557 0 0.04232" group="5"/>
      

      <!-- <body name="arm_mount" pos="-0.0246 0 0.067">
        <geom name="mount_visual" type="box" size="0.0935 0.0525 0.01" material="white" class="visual"/>
        <geom name="mount_collision" type="box" size="0.0935 0.0525 0.01" class="collision"/>      
        
        <geom name="left_rail_visual" type="box" pos="-0.01 0.0285 0.015" size="0.0835 0.0065 0.005" material="gray" class="visual"/>
        <geom name="left_rail_collision" type="box" pos="-0.01 0.0285 0.015" size="0.0835 0.0065 0.005" class="collision"/>

        <geom name="right_rail_visual" type="box" pos="-0.01 -0.0285 0.015" size="0.0835 0.0065 0.005" material="gray" class="visual"/>
        <geom name="right_rail_collision" type="box" pos="-0.01 -0.0285 0.015" size="0.0835 0.0065 0.005" class="collision"/>
        
        <body name="arm" pos="0.0135 0 0.02" childclass="d1">
          <inertial pos="-0.00048697 -2.9605E-12 0.017142" mass="0.077233" fullinertia="0.00010316 0.00011888 0.00018362 -1.0285E-14 2.0449E-07 7.3026E-15"/>
          <geom class="d1_visual" mesh="base_link"/>
          <geom class="d1_collision" mesh="base_link"/> -->
      
      <body name="arm_mount" pos="-0.0256 0 0.067">
        <geom name="mount_visual" type="box" size="0.0925 0.0525 0.01" material="white" class="visual"/>
        <geom name="mount_collision" type="box" size="0.0925 0.0525 0.01" class="collision"/>      
        
        <geom name="left_rail_visual" type="box" pos="-0.0075 0.0285 0.015" size="0.085 0.0065 0.005" material="gray" class="visual"/>
        <geom name="left_rail_collision" type="box" pos="-0.0075 0.0285 0.015" size="0.085 0.0065 0.005" class="collision"/>

        <geom name="right_rail_visual" type="box" pos="-0.0075 -0.0285 0.015" size="0.085 0.0065 0.005" material="gray" class="visual"/>
        <geom name="right_rail_collision" type="box" pos="-0.0075 -0.0285 0.015" size="0.085 0.0065 0.005" class="collision"/>
        
        <body name="arm" pos="0.0185 0 0.02" childclass="d1">
          <inertial pos="-0.00048697 -2.9605E-12 0.017142" mass="0.077233" fullinertia="0.00010316 0.00011888 0.00018362 -1.0285E-14 2.0449E-07 7.3026E-15"/>
          <geom class="d1_visual" mesh="base_link"/>
          <geom class="d1_collision" mesh="base_link"/>

          <body name="link_1" pos="0 0 0.0533" quat="-3.67321e-06 0 0 -1">
            <inertial pos="0.0024649 0.00010517 0.032696" quat="0.999717 -0.0236435 -0.00169588 -0.00221682" mass="0.13174" diaginertia="6.72365e-05 5.41766e-05 4.66199e-05"/>
            <joint name="joint1" type="hinge" axis="0 0 1" range="-2.35 2.35"/>
            <geom class="d1_visual" mesh="Link1"/>
            <geom class="d1_collision" mesh="Link1" contype="0" conaffinity="0"/>
            
            <body name="link_2" pos="0 0.028 0.0563" quat="-2.59734e-06 -2.59735e-06 -0.707108 -0.707105">
              <inertial pos="0.0002018 0.19201 -0.027007" quat="0.706347 0.707865 -0.00093681 0.00051949" mass="0.20213" diaginertia="0.00025682 0.000229681 6.33062e-05"/>
              <joint name="joint2" axis="0 0 -1" range="-1.57 1.57"/>
              <geom class="d1_visual" mesh="Link2"/>
              <geom class="d1_collision" mesh="Link2"/>  
              
              <body name="link_3" pos="0 0.2693 0.0009">
                <inertial pos="0.015164 0.044482 -0.027461" quat="0.690744 0.690771 -0.151176 -0.151179" mass="0.0629" diaginertia="1.84718e-05 1.4964e-05 1.13662e-05"/>
                <joint name="joint3" axis="0 0 -1" range="-1.57 1.57"/>
                <geom class="d1_visual" mesh="Link3"/>
                <geom class="d1_collision" mesh="Link3"/>
                
                <body name="link_4" pos="0.0577 0.042 -0.0275" quat="0.499998 -0.5 0.500002 -0.5">
                  <inertial pos="-0.00029556 -0.00016104 0.091339" quat="0.999998 -3.46195e-05 0.00170171 0.00102754" mass="0.083332" diaginertia="3.93083e-05 3.4378e-05 1.15967e-05"/>
                  <joint name="joint4" axis="0 0 1" range="-2.35 2.35"/>
                  <geom class="d1_visual" mesh="Link4"/>
                  <geom class="d1_collision" mesh="Link4"/>
                  
                  <body name="link_5" pos="-0.0001 -0.0237 0.14018" quat="0.499998 0.5 -0.5 0.500002">
                    <inertial pos="0.040573 0.0062891 -0.023838" quat="0.706153 0.706691 -0.0310982 -0.0311281" mass="0.053817" diaginertia="1.31069e-05 1.1049e-05 8.59523e-06"/>
                    <joint name="joint5" axis="0 0 -1" range="-1.57 1.57"/>
                    <geom class="d1_visual" mesh="Link5"/>
                    <geom class="d1_collision" mesh="Link5"/>
                    
                    <body name="link_6" pos="0.0825 -0.0010782 -0.023822" quat="0.499998 -0.5 0.500002 -0.5">
                      <inertial pos="-0.0068528 -3.9973e-06 0.039705" quat="0.494949 0.495288 -0.504676 0.504992" mass="0.077892" diaginertia="4.8843e-05 3.8232e-05 1.7707e-05"/>
                      <joint name="joint6" axis="0 0 -1" range="-2.35 2.35"/>
                      <geom class="d1_visual" mesh="Link6"/>
                      <geom class="d1_collision" mesh="Link6"/>
                      
                      <site name="tcp_site" pos="0 0 0.1247" quat="1 0 0 -1"/>
                      <site name="grasp_site" pos="0 0 0.1247" quat="1 0 0 -1"/>
                      
                      <body name="link_left_finger" pos="-0.0056012 -0.029636 0.0706" quat="0.499848 -0.50015 -0.49985 -0.500152">
                        <inertial pos="0.018927 0.006 0.012082" quat="0 0.677073 0 0.735916" mass="0.015046" diaginertia="2.62715e-06 2.0229e-06 1.25975e-06"/>
                        <joint name="left_finger" axis="0 0 -1" range="0 0.03" class="finger"/>
                        <geom class="d1_visual" mesh="Link7_1"/>
                        <geom class="d1_collision" mesh="Link7_1"/>
                      </body>
                      
                      <body name="link_right_finger" pos="-0.0056388 0.02964 0.0706" quat="0.500148 0.49985 -0.50015 0.499852">
                        <inertial pos="0.018927 -0.006 0.012082" quat="0 0.677073 0 0.735916" mass="0.015046" diaginertia="2.62715e-06 2.0229e-06 1.25975e-06"/>
                        <joint name="right_finger" axis="0 0 1" range="-0.03 0" class="finger"/>
                        <geom class="d1_visual" mesh="Link7_2"/>
                        <geom class="d1_collision" mesh="Link7_2"/>
                      </body>
                      
                    </body>
                  </body>
                </body>
              </body>
            </body>
          </body>
        </body>
      </body>
      
      <body name="FL_hip" pos="0.1934 0.0465 0">
        <inertial pos="-0.0054 0.00194 -0.000105" quat="0.497014 0.499245 0.505462 0.498237" mass="0.678" diaginertia="0.00088403 0.000596003 0.000479967" />
        <joint name="FL_hip_joint" axis="1 0 0" range="-1.0472 1.0472"/>
        <geom mesh="hip_0" material="metal" class="visual" />
        <geom mesh="hip_1" material="gray" class="visual" />
        <geom name="FL_hip_collision" size="0.046 0.02" pos="0 0.08 0" quat="1 1 0 0" type="cylinder" class="collision" />
        <body name="FL_thigh" pos="0 0.0955 0">
          <inertial pos="-0.00374 -0.0223 -0.0327" quat="0.829533 0.0847635 -0.0200632 0.551623" mass="1.152" diaginertia="0.00594973 0.00584149 0.000878787" />
          <joint name="FL_thigh_joint" axis="0 1 0" range="-1.5708 3.4907"/>
          <geom mesh="thigh_0" material="metal" class="visual" />
          <geom mesh="thigh_1" material="gray" class="visual" />
          <geom name="FL_thigh_collision" size="0.1065 0.01225 0.017" pos="0 0 -0.1065" quat="0.707107 0 0.707107 0" type="box" class="collision" />
          <body name="FL_calf" pos="0 0 -0.213">
            <inertial pos="0.00629595 -0.000622121 -0.141417" quat="0.710672 0.00154099 -0.00450087 0.703508" mass="0.241352" diaginertia="0.0014901 0.00146356 5.31397e-05" />
            <joint name="FL_calf_joint" axis="0 1 0" range="-2.7227 -0.83776"/>
            <geom mesh="calf_0" material="gray" class="visual" />
            <geom mesh="calf_1" material="black" class="visual" />
            <geom name="FL_calf1_collision" size="0.012 0.06" pos="0.008 0 -0.06" quat="0.994493 0 -0.104807 0" type="cylinder" class="collision" />
            <geom name="FL_calf2_collision" size="0.011 0.0325" pos="0.02 0 -0.148" quat="0.999688 0 0.0249974 0" type="cylinder" class="collision" />
            <geom pos="0 0 -0.213" mesh="foot" class="visual" material="black" />
            <geom name="FL_foot_collision" pos="0 0 -0.213" type="sphere" size="0.022" class="collision"/>
            <site name="FL" pos="0 0 -0.213" type="sphere" size="0.022"/>
          </body>
        </body>
      </body>
      <body name="FR_hip" pos="0.1934 -0.0465 0">
        <inertial pos="-0.0054 -0.00194 -0.000105" quat="0.498237 0.505462 0.499245 0.497014" mass="0.678" diaginertia="0.00088403 0.000596003 0.000479967" />
        <joint name="FR_hip_joint" axis="1 0 0" range="-1.0472 1.0472"/>
        <geom mesh="hip_0" material="metal" class="visual" quat="4.63268e-05 1 0 0" />
        <geom mesh="hip_1" material="gray" class="visual" quat="4.63268e-05 1 0 0" />
        <geom name="FR_hip_collision" size="0.046 0.02" pos="0 -0.08 0" quat="0.707107 0.707107 0 0" type="cylinder" class="collision" />
        <body name="FR_thigh" pos="0 -0.0955 0">
          <inertial pos="-0.00374 0.0223 -0.0327" quat="0.551623 -0.0200632 0.0847635 0.829533" mass="1.152" diaginertia="0.00594973 0.00584149 0.000878787" />
          <joint name="FR_thigh_joint" axis="0 1 0" range="-1.5708 3.4907"/>
          <geom mesh="thigh_mirror_0" material="metal" class="visual" />
          <geom mesh="thigh_mirror_1" material="gray" class="visual" />
          <geom name="FR_thigh_collision" size="0.1065 0.01225 0.017" pos="0 0 -0.1065" quat="0.707107 0 0.707107 0" type="box" class="collision" />
          <body name="FR_calf" pos="0 0 -0.213">
            <inertial pos="0.00629595 0.000622121 -0.141417" quat="0.703508 -0.00450087 0.00154099 0.710672" mass="0.241352" diaginertia="0.0014901 0.00146356 5.31397e-05" />
            <joint name="FR_calf_joint" axis="0 1 0" range="-2.7227 -0.83776"/>
            <geom mesh="calf_mirror_0" material="gray" class="visual" />
            <geom mesh="calf_mirror_1" material="black" class="visual" />
            <geom name="FR_calf1_collision" size="0.013 0.06" pos="0.01 0 -0.06" quat="0.995004 0 -0.0998334 0" type="cylinder" class="collision" />
            <geom name="FR_calf2_collision" size="0.011 0.0325" pos="0.02 0 -0.148" quat="0.999688 0 0.0249974 0" type="cylinder" class="collision" />
            <geom pos="0 0 -0.213" mesh="foot" class="visual" material="black" />
            <geom name="FR_foot_collision" pos="0 0 -0.213" type="sphere" size="0.022" class="collision"/>
            <site name="FR" pos="0 0 -0.213" type="sphere" size="0.022"/>
          </body>
        </body>
      </body>
      <body name="RL_hip" pos="-0.1934 0.0465 0">
        <inertial pos="0.0054 0.00194 -0.000105" quat="0.505462 0.498237 0.497014 0.499245" mass="0.678" diaginertia="0.00088403 0.000596003 0.000479967" />
        <joint name="RL_hip_joint" axis="1 0 0" range="-1.0472 1.0472"/>
        <geom mesh="hip_0" material="metal" class="visual" quat="4.63268e-05 0 1 0" />
        <geom mesh="hip_1" material="gray" class="visual" quat="4.63268e-05 0 1 0" />
        <geom name="RL_hip_collision" size="0.046 0.02" pos="0 0.08 0" quat="0.707107 0.707107 0 0" type="cylinder" class="collision" />
        <body name="RL_thigh" pos="0 0.0955 0">
          <inertial pos="-0.00374 -0.0223 -0.0327" quat="0.829533 0.0847635 -0.0200632 0.551623" mass="1.152" diaginertia="0.00594973 0.00584149 0.000878787" />
          <joint name="RL_thigh_joint" axis="0 1 0" range="-0.5236 4.5379"/>
          <geom mesh="thigh_0" material="metal" class="visual" />
          <geom mesh="thigh_1" material="gray" class="visual" />
          <geom name="RL_thigh_collision" size="0.1065 0.01225 0.017" pos="0 0 -0.1065" quat="0.707107 0 0.707107 0" type="box" class="collision" />
          <body name="RL_calf" pos="0 0 -0.213">
            <inertial pos="0.00629595 -0.000622121 -0.141417" quat="0.710672 0.00154099 -0.00450087 0.703508" mass="0.241352" diaginertia="0.0014901 0.00146356 5.31397e-05" />
            <joint name="RL_calf_joint" axis="0 1 0" range="-2.7227 -0.83776"/>
            <geom mesh="calf_0" material="gray" class="visual" />
            <geom mesh="calf_1" material="black" class="visual" />
            <geom name="RL_calf1_collision" size="0.013 0.06" pos="0.01 0 -0.06" quat="0.995004 0 -0.0998334 0" type="cylinder" class="collision" />
            <geom name="RL_calf2_collision" size="0.011 0.0325" pos="0.02 0 -0.148" quat="0.999688 0 0.0249974 0" type="cylinder" class="collision" />
            <geom pos="0 0 -0.213" mesh="foot" class="visual" material="black" />
            <geom name="RL_foot_collision" pos="0 0 -0.213" type="sphere" size="0.022" class="collision"/>
            <site name="RL" pos="0 0 -0.213" type="sphere" size="0.022"/>
          </body>
        </body>
      </body>
      <body name="RR_hip" pos="-0.1934 -0.0465 0">
        <inertial pos="0.0054 -0.00194 -0.000105" quat="0.499245 0.497014 0.498237 0.505462" mass="0.678" diaginertia="0.00088403 0.000596003 0.000479967" />
        <joint name="RR_hip_joint" axis="1 0 0" range="-1.0472 1.0472"/>
        <geom mesh="hip_0" material="metal" class="visual" quat="2.14617e-09 4.63268e-05 4.63268e-05 -1" />
        <geom mesh="hip_1" material="gray" class="visual" quat="2.14617e-09 4.63268e-05 4.63268e-05 -1" />
        <geom name="RR_hip_collision" size="0.046 0.02" pos="0 -0.08 0" quat="0.707107 0.707107 0 0" type="cylinder" class="collision" />
        <body name="RR_thigh" pos="0 -0.0955 0">
          <inertial pos="-0.00374 0.0223 -0.0327" quat="0.551623 -0.0200632 0.0847635 0.829533" mass="1.152" diaginertia="0.00594973 0.00584149 0.000878787" />
          <joint name="RR_thigh_joint" axis="0 1 0" range="-0.5236 4.5379"/>
          <geom mesh="thigh_mirror_0" material="metal" class="visual" />
          <geom mesh="thigh_mirror_1" material="gray" class="visual" />
          <geom name="RR_thigh_collision" size="0.1065 0.01225 0.017" pos="0 0 -0.1065" quat="0.707107 0 0.707107 0" type="box" class="collision" />
          <body name="RR_calf" pos="0 0 -0.213">
            <inertial pos="0.00629595 0.000622121 -0.141417" quat="0.703508 -0.00450087 0.00154099 0.710672" mass="0.241352" diaginertia="0.0014901 0.00146356 5.31397e-05" />
            <joint name="RR_calf_joint" axis="0 1 0" range="-2.7227 -0.83776"/>
            <geom mesh="calf_mirror_0" material="gray" class="visual" />
            <geom mesh="calf_mirror_1" material="black" class="visual" />
            <geom name="RR_calf1_collision" size="0.013 0.06" pos="0.01 0 -0.06" quat="0.995004 0 -0.0998334 0" type="cylinder" class="collision" />
            <geom name="RR_calf2_collision" size="0.011 0.0325" pos="0.02 0 -0.148" quat="0.999688 0 0.0249974 0" type="cylinder" class="collision" />
            <geom pos="0 0 -0.213" mesh="foot" class="visual" material="black" />
            <geom name="RR_foot_collision" pos="0 0 -0.213" type="sphere" size="0.022" class="collision"/>
            <site name="RR" pos="0 0 -0.213" type="sphere" size="0.022"/>
          </body>
        </body>
      </body>
    </body>
  </worldbody>
  
  <sensor>
    <gyro name="imu_ang_vel" site="imu"/>
    <velocimeter name="imu_lin_vel" site="imu"/>
    <accelerometer name="imu_lin_acc" site="imu"/>
    <subtreeangmom name="root_angmom" body="base_link"/>
  </sensor>
  
  <equality>
    <joint joint1="left_finger" joint2="right_finger" polycoef="0 -1 0 0 0"/>
  </equality>
</mujoco>